Workbook

Sheet Terméklista
A1: STÁTUSZ | B1: Fő kat. ID | C1: Fő kat. Neve | D1: Kategória ID | E1: Kat. Neve | F1: Alkat. ID | G1: Alkat. Neve | H1: Szülőtermék | I1: Cikkszám | J1: Terméknév | K1: Státusz (Aktív / Kifutott / Inaktív) | L1: Gyártó | M1: Teljes ár | N1: TB-támogatott ár | O1: KVL Mióta kapható? | P1: Méret | Q1: webshop fotó státusz | R1: Rövid leírás | S1: Hosszú leírás | T1: Üzemmód (CPA/APAP/BiLevel | U1: Nyomástartomány (hPa) | V1: Zajszint (dBA) | W1: Súly (kg) | X1: Méret (szé x ma x mé) | Y1: Holttér (ml) | Z1: Töltési térfogat (ml) | AA1: Párásítási fokozat | AB1: Párásító maximális leadott hőmérséklete | AC1: Szín (fekete/fehér) | AD1: Bluetooth / App kapcsolat (igen/nem) | AE1: Képernyő típusa | AF1: Párásító opció (van/nincs/beépítve) | AG1: Fűtött gégecső opcó (igen/nem) | AH1: SD kártya tartozék? | AI1: Kiszerelés típus (Egy méret / FitPack) | AJ1: Csomag tartalma (részletes) | AK1: Mágneses csat (igen/nem) | AL1: Közgyógyra írtható (igen/nem) | AM1: Jótállás (év) | AN1: Kapcsolódó termékek | AO1: Kapcs. Termékek neve | AP1: Útmutató / Csatolmány link | AQ1: SEO URL | AR1: SEO Meta cím | AS1: SEO Meta leírás | AT1: Webshop státusz | AU1: Megjegyzés (belső) | AV1: Extra kategória
B2: 1. | C2: Alvásterápiás készülékek | D2: 1.1. | E2: CPAP készülékek | I2: LMT 31785-1110 | J2: prisma SMART auto cpap (fekete) | K2: Engedélyezett | L2: Löwenstein | M2: 260350 | N2: 144780 | O2: 45170 | P2: - | Q2: profi | R2: Prémium német auto CPAP készülék a maximális éjszakai nyugalomért. SoftPAP kilégzési könnyítéssel és SoftStart funkcióval teszi természetessé és akadálytalanná a légzést. | S2: A Löwenstein Medical prisma SMART készüléke a német precizitás és a megbízhatóság mintaképe. A készülék szíve egy klinikailag validált algoritmus, amely folyamatosan alkalmazkodik az Ön légzéséhez. A SoftStart funkció segít a könnyű elalvásban, mivel a nyomást csak fokozatosan emeli a terápiás szintre, míg a SoftPAP technológia a kilégzésnél könnyíti meg a légzést, elkerülve a kényszerített érzetet. Halk működése és rendkívüli strapabírása miatt ideális társ a mindennapi terápiához azoknak, akik a stabil, bizonyított technológiát keresik felesleges sallangok nélkül. Fontos információ: A készülék használatához terápiás maszk szükséges, amely külön tétel. Szabványos csatlakozója révén kínálatunk bármelyik maszkjával kompatibilis. | T2: CPAP, APAP | U2: 4-20 hPa | V2: 26 dBA | W2: 1.34 kg | X2: 170x135x180 mm | Z2: - | AC2: fekete | AD2: Nincs | AE2: hagyományos | AF2: Opcionális (fekete) | AG2: ??? Opcionális (külső tápellátással) | AH2: Igen | AI2: Készülék szett | AJ2: Készülék, táska, gégecső, tápegység, tápkábel, 1 db szivacsszűrő, 1 csomag/2db pót szivacsszűrő, útmutató, SD kártya | AK2: - | AL2: Nem | AM2: 2 vagy 3 év (vételár alapján) | AN2: WM 29680; WM 29928; WM 29652; WM 24445; 1147018-01; ??? WM 29067; | AO2: prismaAQUA párásító (fekete); Standard gégecső; Pollenszűrő; Szivacsszűrő; baktériumszűrő; ???prismaHYBERNITE készlet; | AP2: prisma_smart_magyar.pdf | AQ2: lowenstein-prisma-smart-auto-cpap-fekete | AR2: Löwenstein prisma SMART Auto CPAP készülék | Alvásterápia | AS2: Prémium német Löwenstein prisma SMART automata CPAP készülék alvási apnoé kezelésére. Csendes, SoftStart és SoftPAP funkcióval. Szakértői garanciával! | AV2: =VLOOKUP(I2, Kiegészítő_Mátrix!C:E, 3, FALSE) -> #N/A
B3: 1. | C3: Alvásterápiás készülékek | D3: 1.1. | E3: CPAP készülékek | I3: LMT 31920-1110 | J3: prisma SMART plus auto cpap (fehér) | K3: Engedélyezett | L3: Löwenstein | M3: 260350 | N3: 144780 | O3: 45292 | P3: - | Q3: profi | R3: Jövőálló, Bluetooth-kapcsolattal rendelkező német auto CPAP készülék. A prisma APP támogatással és felhő-technológiával nemcsak kényelmet, de modern távfelügyeleti lehetőséget is nyújt. | S3: A Löwenstein Medical prisma SMART PLUS készüléke a német mérnöki precizitást ötvözi a legmodernebb digitális megoldásokkal. A terápiás élmény alapját egy klinikailag validált algoritmus adja, amely folyamatosan figyeli a légzést, és mindig az aktuális szükséglethez igazítja a nyomást. Az elalvást a SoftStart funkció segíti, amely fokozatosan emeli a nyomást a beállított szintre, míg a SoftPAP technológia a kilégzés pillanatában könnyíti meg a légzést a természetes érzet érdekében. A beépített Bluetooth kapcsolat és a prisma APP lehetővé teszi, hogy Ön saját okostelefonján kövesse nyomon a terápia sikerességét. Ez a technológia a jövőben lehetővé teheti a távúton történő kontrollvizsgálatokat, megkönnyítve az orvosi konzultációt. Csendes működése és jövőálló technológiája hosszú távú, biztonságos megoldást nyújt az alvási apnoé kezelésében. Fontos információ: A készülék használatához terápiás maszk szükséges, amely külön tétel. Szabványos csatlakozója révén kínálatunk bármelyik maszkjával kompatibilis. | T3: CPAP, APAP | U3: 4-20 hPa | V3: 26 dBA | W3: 1.34 kg | X3: 170x135x180 mm | Z3: - | AC3: fehér | AD3: Igen | AE3: hagyományos | AF3: Opcionális (fehér) | AG3: ??? Opcionális (külső tápellátással) | AH3: Igen | AI3: Készülék szett | AJ3: Készülék, táska, gégecső, tápegység, tápkábel, szivacsszűrő, 1 csomag/2db pót szivacsszűrő, útmutató, SD kártya | AK3: - | AL3: Nem | AM3: 2 vagy 3 év (vételár alapján) | AN3: WM 29490; WM 29928; WM 29652; WM 24445; 1147018-01; ??? WM 29067; | AO3: prismaAQUA párásító (fehér); Standard gégecső; Pollenszűrő; Szivacsszűrő; Baktériumszűrő; ???prismaHYBERNITE készlet; | AP3: prisma_smart_plus_HU.pdf | AQ3: lowenstein-prisma-smart-plus-auto-cpap-feher | AR3: Löwenstein prisma SMART plus Auto CPAP gép | Alvásterápia | AS3: Löwenstein prisma SMART plus CPAP készülék beépített Bluetooth kapcsolattal, app-követéssel és halk működéssel. Szakértői szerviz és megbízható támogatás. | AV3: =VLOOKUP(I3, Kiegészítő_Mátrix!C:E, 3, FALSE) -> #N/A
B4: 1. | C4: Alvásterápiás készülékek | D4: 1.1. | E4: CPAP készülékek | I4: WM 29600-1 | J4: Prisma A20 auto cpap | K4: Engedélyezett | L4: Löwenstein | M4: 299720 | N4: NEM ELÉRHETŐ | O4: 42064 | P4: - | Q4: profi | R4: A prisma-család prémium, érintőképernyős tagja FOT technológiával a pontosabb diagnózisért. | S4: A Löwenstein prisma 20A a német precizitás csúcsa. A Forced Oscillation Technique (FOT) segítségével nagy pontossággal különbözteti meg az obstruktív és centrális apnoékat. Színes érintőképernyőjén minden beállítás könnyen elérhető. A SoftPAP kilégzési könnyítés három fokozatban állítható, a mélyalvás-jelző pedig segít az alvásminőség pontos értékelésében. Fontos információ: A készülék használatához terápiás maszk szükséges, amely külön tétel. Szabványos csatlakozója révén kínálatunk bármelyik maszkjával kompatibilis. | T4: CPAP, APAP | U4: 4-20 hPa | V4: 26 dBA | W4: 1.4 kg | X4: 170x135x180 mm | Z4: - | AC4: fekete | AD4: Nincs | AE4: érintőképernyős | AF4: Opcionális (fekete) | AG4: ??? Opcionális (külső tápellátással) | AH4: Igen | AI4: Készülék szett | AJ4: Készülék, táska, gégecső, tápegység, tápkábel, szivacsszűrő, útmutató, SD kártya | AK4: - | AL4: Nem | AM4: 3 év | AN4: WM 29680; WM 29928; WM 29652; WM 24445; 1147018-01; ??? WM 29067; | AO4: prismaAQUA párásító; Szivacsszűrő; Pollenszűrő; Standard gégecső; Baktériumszűrő; ???prismaHYBERNITE készlet; | AP4: prisma_20A_hasznalati.pdf | AQ4: lowenstein-prisma-20a-auto-cpap | AR4: Löwenstein Prisma 20A Auto CPAP készülék | Alvásterápia | AS4: Érintőképernyős Löwenstein Prisma 20A prémium CPAP gép FOT technológiával a precíz apnoé kezelésért. Halk üzem, SoftPAP könnyítés és orvosi megbízhatóság. | AT4: angol | AV4: =VLOOKUP(I4, Kiegészítő_Mátrix!C:E, 3, FALSE) -> #N/A
B5: 1. | C5: Alvásterápiás készülékek | D5: 1.1. | E5: CPAP készülékek | I5: EUX500S15 | J5: DreamStation auto cpap | K5: Engedélyezett | L5: Philips | M5: 298450 | N5: 182880 | O5: 42522 | P5: - | Q5: profi | R5: Világszerte elismert, prémium auto CPAP készülék A-Flex nyomáskönnyítéssel és elegáns megjelenéssel. | S5: A Philips DreamStation a terápiás hatékonyságot ötvözi a modern dizájnnal. Az A-Flex technológia a természetes légzés ritmusát követve szabályozza a nyomást, így elkerülhető a légszomj érzése. Színes kijelzője és intuitív menüje egyszerűvé teszi az adatok követését, a beépített Bluetooth segítségével pedig okostelefonon is láthatja statisztikáit. Fontos információ: A készülék használatához terápiás maszk szükséges, amely külön tétel. Szabványos csatlakozója révén kínálatunk bármelyik maszkjával kompatibilis. | T5: CPAP, APAP | U5: 4-20 cmH2O | V5: 27 dBA | W5: 1.33 kg | X5: 157x193x84 mm | Z5: - | AC5: fehér/szürke | AD5: Igen | AE5: hagyományos | AF5: Opcionális | AG5: Opcionális | AH5: Igen | AI5: Készülék szett | AJ5: Készülék, táska, gégecső, tápegység, tápkábel, szivacsszűrő, útmutató, SD kártya | AK5: - | AL5: Nem | AM5: 2 vagy 3 év (vételár alapján) | AN5: EUXH; 1122446; 1122519; 1147018-01 | AO5: DreamStation párásító; Szivacsszűrő; Pollenszűrő; Baktériumszűrő | AP5: dreamstation_manual_hu.pdf | AQ5: philips-dreamstation-auto-cpap | AR5: Philips DreamStation Auto CPAP készülék | Alvásterápia | AS5: Elegáns Philips DreamStation automata CPAP készülék A-Flex kilégzési nyomáskönnyítéssel, intuitív kezeléssel és csendes terápiás működéssel. Rendelje meg! | AV5: =VLOOKUP(I5, Kiegészítő_Mátrix!C:E, 3, FALSE) -> #N/A
B6: 1. | C6: Alvásterápiás készülékek | D6: 1.1. | E6: CPAP készülékek | I6: EEX520H15C | J6: DreamStation2 auto cpap | K6: Engedélyezett | L6: Philips | M6: 317500 | N6: NEM ELÉRHETŐ | O6: 46023 | P6: - | Q6: nincs | R6: A Philips legújabb generációs, érintőképernyős auto CPAP készüléke beépített párásítóval. Intelligens algoritmusa minden légvételre azonnal reagál, adatai pedig automatikusan szinkronizálódnak. | S6: A Philips DreamStation 2 az intelligens alvásterápia legújabb generációja, amely kompakt méretben nyújt maximális kényelmet. Működési elve az automatikus nyomásszabályozáson alapul: a készülék minden egyes légvételt elemez, és azonnal korrigálja a nyomást a légutak nyitvatartása érdekében, így biztosítva a pihentető alvást. A színes érintőképernyő és az integrált, fűthető párásító rendkívül egyszerűvé teszi a mindennapi használatot. Egyedülálló módon beépített modem és Bluetooth segítségével az adatok automatikusan szinkronizálódnak a felhőbe, így a terápiás információk SD-kártya nélkül is biztonságosan elérhetőek maradnak. A készülék minden reggel visszajelzést ad a maszk illeszkedéséről és a terápia hatékonyságáról, segítve Önt a magabiztos használatban. Fontos információ: A készülék használatához terápiás maszk szükséges, amely külön tétel. Szabványos csatlakozója révén kínálatunk bármelyik maszkjával kompatibilis. | T6: CPAP, APAP | U6: 4 - 20 hPa | V6: 27 dBA | W6: 1.04 kg (párásítóval) | X6: 273.8 x 158.5 x 84.8 mm | Z6: - | AC6: fekete | AD6: Igen (+ Celluláris modem) | AE6: érintőképernyős | AF6: Beépített | AG6: Opcionális | AH6: Nem (belső memória) | AI6: Készülék szett | AJ6: Készülék beépített párásítóval, hordtáska, vékonyított gégecső, tápegység, tápkábel, szivacsszűrő, használati útmutató | AK6: - | AL6: Nem | AM6: 3 év | AN6: EUXH; 1122446; 1122519; 1147018-01 | AO6: DreamStation párásító; Szivacsszűrő; Pollenszűrő; Baktériumszűrő | AP6: dreamstation2_hasznalati.pdf | AQ6: philips-dreamstation-2-auto-cpap | AR6: Philips DreamStation 2 Auto CPAP készülék | Alvásterápia | AS6: Új generációs Philips DreamStation 2 auto CPAP színes érintőképernyővel és beépített párásítóval. Kompakt méret, intelligens algoritmus és maximális kényelem. | AV6: =VLOOKUP(I6, Kiegészítő_Mátrix!C:E, 3, FALSE) -> #N/A
B7: 1. | C7: Alvásterápiás készülékek | D7: 1.1. | E7: CPAP készülékek | I7: 112000205 | J7: AeonMed AS100A auto cpap | K7: Engedélyezett | M7: 247650 | N7: NEM ELÉRHETŐ | O7: 44927 | P7: - | Q7: nincs | R7: Innovatív, érintőképernyős auto CPAP készülék a német Heier szakmai támogatásával. Kompakt design és intelligens technológia a modern alvásterápiáért. | S7: Az AeonMed AS100A a globális orvostechnikai innováció egyik legmodernebb eszköze, melyet a kínai gyártó a neves német Heier céggel szoros szakmai együttműködésben fejlesztett ki. Rendkívül könnyű és modern készülék, a 3,5 colos érintőképernyője és az AS-Elex 7 fokozatú nyomáskönnyítése kiemelkedő komfortot nyújt. Az AS-Dry technológia a terápia végén kiszárítja a gégecsövet és a maszkot, megakadályozva a baktériumok szaporodását. Kis súlya miatt ideális utazóknak, akik nem akarnak kompromisszumot a biztonságban. Fontos információ: A készülék használatához terápiás maszk szükséges, amely külön tétel. Szabványos csatlakozója révén kínálatunk bármelyik maszkjával kompatibilis. | T7: CPAP, APAP | U7: 4-20 hPa | V7: <30 dBA | W7: 0.82 kg | X7: 160x148x99,5 mm | Z7: - | AC7: fekete | AD7: Nincs | AE7: érintőképernyős | AF7: Opcionális | AG7: Nem elérhető | AH7: Igen | AI7: Készülék szett | AJ7: Készülék, táska, gégecső, tápegység, tápkábel, szűrők, útmutató, SD kártya | AK7: - | AL7: Nem | AM7: 2 vagy 3 év (vételár alapján) | AN7: 122014265; AS100_filter | AO7: párásító; AS100 szűrő készlet | AP7: as100a_manual_hu.pdf | AQ7: aeonmed-as100a-auto-cpap-keszulek | AR7: AeonMed AS100A Auto CPAP készülék | Alvásterápia | AS7: Megbízható, érintőképernyős AeonMed AS100A automata CPAP gép csendes üzemeléssel és intelligens nyomásszabályozással alvási apnoé kezelésére. Kérjen segítséget! | AV7: =VLOOKUP(I7, Kiegészítő_Mátrix!C:E, 3, FALSE) -> #N/A
P8: - | AV8: =VLOOKUP(I8, Kiegészítő_Mátrix!C:E, 3, FALSE) -> #N/A
B9: 1. | C9: Alvásterápiás készülékek | D9: 1.2 | E9: BiPAP készülékek | I9: WM 29900-1 | J9: prisma 25S auto BiPAP | K9: Engedélyezett | L9: Löwenstein | M9: 615950 | N9: 336550 | O9: 44378 | P9: - | Q9: profi | R9: Prémium BiLevel készülék komplex légzési problémák és magas nyomásigény hatékony kezelésére. | S9: A Löwenstein Medical prisma 25S egy professzionális terápiás eszköz, amely túllép a hagyományos CPAP határain. Kifejezetten olyan pácienseknek tervezték, akiknél az elhízásos hipoventiláció vagy a COPD miatt két, markánsan eltérő nyomásszintre van szükség a belégzéshez és a kilégzéshez. A készülék egyedülálló trigger-technológiája felismeri a páciens legkisebb légzési erőfeszítését is, és azonnal segíti azt. A német precizitású algoritmus és a SoftPAP technológia gondoskodik arról, hogy a terápia még extrém magas nyomáson is komfortos maradjon, minimálisra csökkentve a tüdő terhelését. Fontos információ: A készülék használatához terápiás maszk szükséges, amely külön tétel. Szabványos csatlakozója révén kínálatunk bármelyik maszkjával kompatibilis. | T9: CPAP, APAP, S, autoS | U9: 4-25 hPa | V9: 26 dBA | W9: 1.4 kg | X9: 170x135x180 mm | Z9: - | AC9: fekete | AD9: Nincs | AE9: érintőképernyős | AF9: Opcionális (fekete) | AG9: ??? Opcionális (külső tápellátással) | AH9: Igen | AI9: Készülék szett | AJ9: Készülék, táska, gégecső, tápegység, tápkábel, szivacsszűrő, útmutató, SD kártya | AK9: - | AL9: Nem | AM9: 3 év | AN9: WM 29680; ???WM 29067; 1147018-01; WM 24445; WM 29652; WM 29928; | AO9: prismaAQUA (fekete); ???prismaHYBERNITE készlet; Baktériumszűrő; Gégecső; Pollenszűrő, Szivacsszűrő | AP9: magyarul - önálló file A20-al együtt Weinmann | AQ9: lowenstein-prisma-25s-auto-bipap | AR9: Löwenstein prisma 25S Auto BiPAP készülék | Alvásterápia | AS9: Prémium Löwenstein prisma 25S automata BiLevel készülék magas nyomásigényre és komplex apnoéra. Csendes működés, SoftPAP és szakértői szerviztámogatás. | AV9: =VLOOKUP(I9, Kiegészítő_Mátrix!C:E, 3, FALSE) -> #N/A
B10: 1. | C10: Alvásterápiás készülékek | D10: 1.2 | E10: BiPAP készülékek | I10: WM 29930-2 | J10: prisma30ST | K10: Engedélyezett | L10: Löwenstein | M10: 1257300 | N10: NEM ELÉRHETŐ | O10: 44378 | P10: - | Q10: profi | R10: Professzionális BiLevel-ST készülék komplex terápiás igényekhez. | S10: A Löwenstein Medical prisma 30ST a BiLevel terápia csúcsát képviseli, amely maximális biztonságot nyújt a legkomplexebb légzészavarok esetén is. Kifejezetten olyan súlyosabb állapotú betegeknek fejlesztették ki, akiknél a légzés folyamatos támogatása mellett egy biztonsági háttérfrekvenciára (ST üzemmód) is szükség van, például központi apnoe vagy krónikus légzési elégtelenség fennállásakor. Az intelligens autoST algoritmus folyamatosan alkalmazkodik a beteg egyéni igényeihez, garantálva a szükséges levegőmennyiséget és az optimális oxigénszintet a legnehezebb éjszakai szakaszokban is. A modern érintőképernyő és a rendkívül halk működés a legmagasabb szintű betegkomfortot szolgálja. Fontos információ: A készülék használatához terápiás maszk szükséges, amely külön tétel. Szabványos csatlakozója révén kínálatunk bármelyik maszkjával kompatibilis. | T10: CPAP, APAP, S, ST, T, autoST, aPCV | U10: 4-30 hPa | V10: 26 dB(A) | W10: 1,4 kg | X10: 170 x 135 x 180 mm | Z10: - | AC10: fekete | AD10: Nincs | AE10: érintőképernyős | AF10: Opcionális (fekete) | AG10: ??? Opcionális (külső tápellátással) | AH10: Igen | AI10: Készülék szett | AJ10: Készülék, táska, gégecső, tápegység, tápkábel, szivacsszűrő, útmutató, SD kártya | AK10: - | AL10: Nem | AM10: 3 év | AN10: WM 29680; ???WM 29067; 1147018-01; WM 24445; WM 29652; WM 29928; | AO10: prismaAQUA (fekete); ???prismaHYBERNITE készlet; Baktériumszűrő; Gégecső; Pollenszűrő, Szivacsszűrő | AP10: magyarul - önálló file A20-al együtt Weinmann | AQ10: lowenstein-prisma-30st-bilevel-keszulek | AR10: Löwenstein prisma30ST BiLevel-ST készülék | Alvásterápia | AS10: Professzionális Löwenstein prisma30ST BiLevel-ST terápiás készülék komplex igényekre. Precíz német technológia, halk üzem és megbízható szervizháttér. | AV10: =VLOOKUP(I10, Kiegészítő_Mátrix!C:E, 3, FALSE) -> #N/A
B11: 1. | C11: Alvásterápiás készülékek | D11: 1.2 | E11: BiPAP készülékek | I11: WM 29960-2110 | J11: prismaCR | K11: Engedélyezett | L11: Löwenstein | M11: 1587500 | N11: NEM ELÉRHETŐ | O11: 44378 | P11: - | Q11: nincs | R11: Speciális AcSV készülék periodikus légzészavarok és szívelégtelenség melletti apnoe kezelésére. | S11: A Löwenstein Medical prisma CR az anticiklikus szervoventiláció (AcSV) technológiájával a periodikus légzészavarok, például a Cheyne-Stokes légzés elismert szakértője. Ezt a professzionális eszközt kifejezetten szívbetegséggel küzdő pácienseknek és komplex alvási apnoéban szenvedőknek tervezték, hogy lélegzetről lélegzetre stabilizálja a szabálytalan légzésmintázatot. A készülék rendkívül gyorsan reagál a légzés intenzitásának változásaira, hatékonyan megakadályozva a fulladásérzetet és a gyakori mikroébredéseket. A német mérnöki precizitás garantálja, hogy a terápia hajszálpontosan kövesse a beteg igényeit, biztosítva a pihentető és biztonságos alvást. Fontos információ: A készülék használatához terápiás maszk szükséges, amely külön tétel. Szabványos csatlakozója révén kínálatunk bármelyik maszkjával kompatibilis. | T11: CPAP, AcSV, (Anticiklikus szervoventiláció) | U11: 4-30 hPa | V11: 26 dBA | W11: 1.4 kg | X11: 170x135x180 mm | Z11: - | AC11: fekete | AD11: Nincs | AE11: érintőképernyős | AF11: Opcionális (fekete) | AG11: Opcionális (külső táp.) | AH11: Igen | AI11: Készülék szett | AJ11: Készülék, táska, gégecső, tápegység, tápkábel, szivacsszűrő, útmutató, SD kártya | AK11: - | AL11: Nem | AM11: 3 év | AN11: WM 29680; ???WM 29067; 1147018-01; 1116700; WM 24445 | AO11: prismaAQUA; ???prismaHYBERNITE; Baktériumszűrő; Pollenszűrő; Szivacsszűrő; | AP11: magyarul - önálló file A20-al együtt Weinmann | AQ11: lowenstein-prisma-cr-acsv-keszulek | AR11: Löwenstein prismaCR AcSV terápiás készülék | Alvásterápia | AS11: Speciális Löwenstein prismaCR szervo-lélegeztető készülék komplex és periodikus légzészavarokra. Orvostechnikai precizitás és megbízható szakértői háttér. | AV11: =VLOOKUP(I11, Kiegészítő_Mátrix!C:E, 3, FALSE) -> #N/A
B12: 1. | C12: Alvásterápiás készülékek | D12: 1.2 | E12: BiPAP készülékek | I12: ? | J12: Dreamstation Bipap? | AP12: magyarul - önálló file | AV12: =VLOOKUP(I12, Kiegészítő_Mátrix!C:E, 3, FALSE) -> #N/A
AV13: =VLOOKUP(I13, Kiegészítő_Mátrix!C:E, 3, FALSE) -> #N/A
B14: 1. | C14: Alvásterápiás készülékek | D14: 1.3 | E14: Kifutott készülékek | I14: WM 27420/s | J14: SomnoBalance (e) auto cpap fehér | K14: Kifutott | L14: Löwenstein | O14: 42036 | Q14: profi | R14: Megbízható klasszikus készülék (Kifutott típus). | S14: FIGYELEM – KIFUTOTT MODELL: Ez a készülék már nem rendelhető. Az orvostechnikai eszközökre vonatkozó gyártói javaslatok és a TB támogatási ciklus alapján a készülékek optimális élettartama 5 év. A 7-8 évnél idősebb gépek esetében az alkatrészellátás már nem garantált. Javasolt utódmodell: prisma SMART (halkabb, modernebb, precízebb). | AN14: WM 24403; WM 24445; WM 15321; WM 25668; 1147018-01 | AO14: párásító, gégecső, szivacsszűrő, pollenszűrő, baktériumszűrő | AP14: magyarul - önálló file | AQ14: lowenstein-somnobalance-cpap-tartozekok | AR14: Löwenstein SomnoBalance CPAP alkatrészek | Alvásterápia | AS14: Eredeti gyári szűrők, gégecsövek és pótalkatrészek a kifutott Löwenstein SomnoBalance készülékhez. Tartsa karban meglévő CPAP gépét megbízhatóan! | AV14: =VLOOKUP(I14, Kiegészítő_Mátrix!C:E, 3, FALSE) -> #N/A
B15: 1. | C15: Alvásterápiás készülékek | D15: 1.3 | E15: Kifutott készülékek | I15: IN561 | J15: Remstar Auto A-Flex | K15: Kifutott | L15: Philips | O15: 41214 | Q15: profi | R15: Korábbi generációs CPAP készülék (Kifutott típus) | S15: FIGYELEM – KIFUTOTT MODELL: Ez a készülék már nem rendelhető. Az orvostechnikai eszközökre vonatkozó gyártói javaslatok és a TB támogatási ciklus alapján a készülékek optimális élettartama 5 év. A 7-8 évnél idősebb gépek esetében az alkatrészellátás már nem garantált. Javasolt utódmodell: prisma SMART (halkabb, modernebb, precízebb). | AN15: 1029330; 1029331; 1032907 | AO15: Remstar szivacsszűrő, pollenszűrő; gégecső | AP15: van (Csilla mappa) | AQ15: philips-remstar-auto-aflex-tartozekok | AR15: Philips Remstar Auto A-Flex CPAP alkatrészek | Alvásterápia | AS15: Kompatibilis szűrők, víztartályok és tartozékok Philips Remstar Auto A-Flex gépekhez. Kifutott típus megbízható gyári alkatrész- és szervizellátással. | AV15: =VLOOKUP(I15, Kiegészítő_Mátrix!C:E, 3, FALSE) -> #N/A
B16: 1. | C16: Alvásterápiás készülékek | D16: 1.3 | E16: Kifutott készülékek | I16: IN461S | J16: Remstar pro C-Flex | K16: Kifutott | L16: Philips | O16: 42795 | Q16: nincs | R16: Korábbi generációs CPAP készülék (Kifutott típus) | S16: FIGYELEM – KIFUTOTT MODELL: Ez a készülék már nem rendelhető. Az orvostechnikai eszközökre vonatkozó gyártói javaslatok és a TB támogatási ciklus alapján a készülékek optimális élettartama 5 év. A 7-8 évnél idősebb gépek esetében az alkatrészellátás már nem garantált. Javasolt utódmodell: prisma SMART (halkabb, modernebb, precízebb). | AN16: 1029330; 1029331; 1032907 | AO16: Remstar szivacsszűrő, pollenszűrő; gégecső | AP16: van Cintia használati | AQ16: philips-remstar-pro-cflex-tartozekok | AR16: Philips Remstar Pro C-Flex CPAP tartozékok | Alvásterápia | AS16: Gyári szűrők, tápegységek és alkatrészek a kifutott Philips Remstar Pro C-Flex készülékhez. Rendeljen pótalkatrészt közvetlenül szaküzletünkből! | AV16: =VLOOKUP(I16, Kiegészítő_Mátrix!C:E, 3, FALSE) -> #N/A
B17: 1. | C17: Alvásterápiás készülékek | D17: 1.3 | E17: Kifutott készülékek | I17: IN751S | J17: BiPAP Auto IN751S | K17: Kifutott | L17: Philips | O17: 40528 | Q17: van | R17: Korábbi generációs BiPAP készülék (Kifutott típus) | S17: FIGYELEM – KIFUTOTT MODELL: Ez a készülék már nem rendelhető. Az orvostechnikai eszközökre vonatkozó gyártói javaslatok és a TB támogatási ciklus alapján a készülékek optimális élettartama 5 év. A 7-8 évnél idősebb gépek esetében az alkatrészellátás már nem garantált. Javasolt utódmodell: prisma SMART (halkabb, modernebb, precízebb). | AN17: 1029330; 1029331; 1032907 | AO17: Remstar szivacsszűrő, pollenszűrő; gégecső | AQ17: philips-bipap-auto-in751s-alkatreszek | AR17: Philips BiPAP Auto IN751S alkatrészek | Alvásterápia | AS17: Eredeti szűrők, maszkok és kiegészítők a korábbi Philips BiPAP Auto IN751S készülékhez. Biztosítsa meglévő terápiás gépe zavartalan működését! | AV17: =VLOOKUP(I17, Kiegészítő_Mátrix!C:E, 3, FALSE) -> #N/A
B18: 1. | C18: Alvásterápiás készülékek | D18: 1.3 | E18: Kifutott készülékek | I18: IN701S | J18: BiPAP Auto M IN701S | K18: Kifutott | L18: Philips | O18: 40528 | Q18: van | R18: Korábbi generációs BiPAP készülék (Kifutott típus) | S18: FIGYELEM – KIFUTOTT MODELL: Ez a készülék már nem rendelhető. Az orvostechnikai eszközökre vonatkozó gyártói javaslatok és a TB támogatási ciklus alapján a készülékek optimális élettartama 5 év. A 7-8 évnél idősebb gépek esetében az alkatrészellátás már nem garantált. Javasolt utódmodell: prisma SMART (halkabb, modernebb, precízebb). | AN18: 1029330; 1029331; 1032907 | AO18: Remstar szivacsszűrő, pollenszűrő; gégecső | AQ18: philips-bipap-auto-m-in701s-tartozekok | AR18: Philips BiPAP Auto M IN701S tartozékok | Alvásterápia | AS18: Kompatibilis szűrők, tápkábelek és alkatrészek a kifutott Philips BiPAP Auto M sorozathoz. Gyors alkatrészpótlás és szakértői háttértámogatás. | AV18: =VLOOKUP(I18, Kiegészítő_Mátrix!C:E, 3, FALSE) -> #N/A
B19: 1. | C19: Alvásterápiás készülékek | D19: 1.3 | E19: Kifutott készülékek | I19: IN171 | J19: Remstar CPAP Flex IN171 | K19: Kifutott | L19: Philips | O19: 41228 | Q19: van | R19: Korábbi generációs CPAP készülék (Kifutott típus) | S19: FIGYELEM – KIFUTOTT MODELL: Ez a készülék már nem rendelhető. Az orvostechnikai eszközökre vonatkozó gyártói javaslatok és a TB támogatási ciklus alapján a készülékek optimális élettartama 5 év. A 7-8 évnél idősebb gépek esetében az alkatrészellátás már nem garantált. Javasolt utódmodell: prisma SMART (halkabb, modernebb, precízebb). | AN19: 1029330; 1029331; 1032907 | AO19: Remstar szivacsszűrő, pollenszűrő; gégecső | AQ19: philips-remstar-cpap-flex-in171-tartozekok | AR19: Philips Remstar CPAP Flex IN171 alkatrészek | Alvásterápia | AS19: Porszűrők, pollenszűrők és kiegészítők a Philips Remstar Flex IN171 készülékhez. Megbízható alkatrészellátás és szerviztámogatás kifutott gépekhez. | AV19: =VLOOKUP(I19, Kiegészítő_Mátrix!C:E, 3, FALSE) -> #N/A
B20: 1. | C20: Alvásterápiás készülékek | D20: 1.3 | E20: Kifutott készülékek | I20: IN251S | J20: Remstar CPAP Flex IN251S | K20: Kifutott | L20: Philips | O20: 41153 | Q20: van | R20: Korábbi generációs CPAP készülék (Kifutott típus) | S20: FIGYELEM – KIFUTOTT MODELL: Ez a készülék már nem rendelhető. Az orvostechnikai eszközökre vonatkozó gyártói javaslatok és a TB támogatási ciklus alapján a készülékek optimális élettartama 5 év. A 7-8 évnél idősebb gépek esetében az alkatrészellátás már nem garantált. Javasolt utódmodell: prisma SMART (halkabb, modernebb, precízebb). | AN20: 1029330; 1029331; 1032907 | AO20: Remstar szivacsszűrő, pollenszűrő; gégecső | AQ20: philips-remstar-cpap-flex-in251s-szurok | AR20: Philips Remstar Flex IN251S alkatrészek | Alvásterápia | AS20: Rendeljen eredeti szűrőket és gégecsöveket a klasszikus Philips Remstar Flex IN251S CPAP gépéhez. Fenntartás és tartozékok szakértői garanciával. | AV20: =VLOOKUP(I20, Kiegészítő_Mátrix!C:E, 3, FALSE) -> #N/A
B21: 1. | C21: Alvásterápiás készülékek | D21: 1.3 | E21: Kifutott készülékek | I21: IN101 | J21: Remstar M CPAP IN101 | K21: Kifutott | L21: Philips | O21: 40528 | Q21: van | R21: Korábbi generációs CPAP készülék (Kifutott típus) | S21: FIGYELEM – KIFUTOTT MODELL: Ez a készülék már nem rendelhető. Az orvostechnikai eszközökre vonatkozó gyártói javaslatok és a TB támogatási ciklus alapján a készülékek optimális élettartama 5 év. A 7-8 évnél idősebb gépek esetében az alkatrészellátás már nem garantált. Javasolt utódmodell: prisma SMART (halkabb, modernebb, precízebb). | AN21: 1029330; 1029331; 1032907 | AO21: Remstar szivacsszűrő, pollenszűrő; gégecső | AQ21: philips-remstar-m-cpap-in101-tartozekok | AR21: Philips Remstar M CPAP IN101 alkatrészek | Alvásterápia | AS21: Kompatibilis szivacsszűrők, finomszűrők és tartozékok a korábbi generációs Philips Remstar M sorozathoz. Gondoskodjon készüléke tiszta üzemeléséről! | AV21: =VLOOKUP(I21, Kiegészítő_Mátrix!C:E, 3, FALSE) -> #N/A
B22: 1. | C22: Alvásterápiás készülékek | D22: 1.3 | E22: Kifutott készülékek | I22: IN761S | J22: BiPAP Auto BiFlex System one | K22: Kifutott | L22: Philips | O22: 41275 | Q22: van | R22: Korábbi generációs BiPAP készülék (Kifutott típus) | S22: FIGYELEM – KIFUTOTT MODELL: Ez a készülék már nem rendelhető. Az orvostechnikai eszközökre vonatkozó gyártói javaslatok és a TB támogatási ciklus alapján a készülékek optimális élettartama 5 év. A 7-8 évnél idősebb gépek esetében az alkatrészellátás már nem garantált. Javasolt utódmodell: prisma SMART (halkabb, modernebb, precízebb). | AN22: 1029330; 1029331; 1032907 | AO22: Remstar szivacsszűrő, pollenszűrő; gégecső | AP22: van (Csilla mappa) | AQ22: philips-bipap-auto-system-one-alkatreszek | AR22: Philips System One BiPAP alkatrészek | Alvásterápia | AS22: Gyári System One víztartályok, pollenszűrők és csövek Philips BiPAP Auto készülékekhez. Kifutott típus megbízható alkatrész- és tartozékellátással. | AV22: =VLOOKUP(I22, Kiegészítő_Mátrix!C:E, 3, FALSE) -> #N/A
B23: 1. | C23: Alvásterápiás készülékek | D23: 1.3 | E23: Kifutott készülékek | I23: IN961S | J23: BiPAP AutoSV | K23: Kifutott | L23: Philips | O23: 41518 | Q23: van | R23: Korábbi generációs BiPAP készülék (Kifutott típus) | S23: FIGYELEM – KIFUTOTT MODELL: Ez a készülék már nem rendelhető. Az orvostechnikai eszközökre vonatkozó gyártói javaslatok és a TB támogatási ciklus alapján a készülékek optimális élettartama 5 év. A 7-8 évnél idősebb gépek esetében az alkatrészellátás már nem garantált. Javasolt utódmodell: prisma SMART (halkabb, modernebb, precízebb). | AN23: 1029330; 1029331; 1032907 | AO23: Remstar szivacsszűrő, pollenszűrő; gégecső | AP23: van szkennelt (fordítások2) | AQ23: philips-bipap-autosv-tartozekok | AR23: Philips BiPAP AutoSV készülék alkatrészek | Alvásterápia | AS23: Speciális tartozékok, szűrők és légzőcsövek a Philips BiPAP AutoSV terápiás géphez. Szakértői háttér és kompatibilis kiegészítők kifutott modellekhez. | AV23: =VLOOKUP(I23, Kiegészítő_Mátrix!C:E, 3, FALSE) -> #N/A
B24: 1. | C24: Alvásterápiás készülékek | D24: 1.3 | E24: Kifutott készülékek | I24: IN1161X | J24: BiPAP Avaps | K24: Kifutott | L24: Philips | O24: 43101 | Q24: van | R24: Korábbi generációs BiPAP készülék (Kifutott típus) | S24: FIGYELEM – KIFUTOTT MODELL: Ez a készülék már nem rendelhető. Az orvostechnikai eszközökre vonatkozó gyártói javaslatok és a TB támogatási ciklus alapján a készülékek optimális élettartama 5 év. A 7-8 évnél idősebb gépek esetében az alkatrészellátás már nem garantált. Javasolt utódmodell: prisma SMART (halkabb, modernebb, precízebb). | AN24: 1029330; 1029331; 1032907 | AO24: Remstar szivacsszűrő, pollenszűrő; gégecső | AQ24: philips-bipap-avaps-alkatreszek | AR24: Philips BiPAP AVAPS alkatrészek és szűrők | Alvásterápia | AS24: Gyári szűrők, tápegységek és gégecsövek Philips BiPAP AVAPS lélegeztető készülékhez. Tartsa megbízható állapotban gépe alkatrész-ellátottságát! | AV24: =VLOOKUP(I24, Kiegészítő_Mátrix!C:E, 3, FALSE) -> #N/A
AV25: =VLOOKUP(I25, Kiegészítő_Mátrix!C:E, 3, FALSE) -> #N/A
B26: 2. | C26: Párásítók | I26: WM 29490 | J26: Prisma Aqua párásító fehér | K26: Engedélyezett | L26: Löwenstein | M26: 80010 | N26: 40005 | O26: 44197 | P26: - | Q26: profi | R26: Fűthető párásító prisma SMART és a prisma SMART Plus készülékekhez, fehér színben. | S26: A prismaAQUA fűthető párásító a terápiás komfort növelésének kulcsfontosságú eszköze, amely megakadályozza a légutak és a szájnyálkahártya kiszáradását. A készülékbe észrevétlenül integrálható egység fűtési intenzitása a CPAP készülék menüjéből egyszerűen szabályozható 5 fokozatban, így a páratartalom mindig a páciens egyéni igényeihez igazítható. A tartály kialakítása lehetővé teszi a könnyű töltést és a higiénikus tisztítást. Fontos előírás, hogy a párásító használatával egyidejűleg a kerek baktériumszűrő alkalmazása tilos! Az Ön egészségének, valamint a párásító élettartamának megőrzése érdekében desztillált víz használata javasolt. További hasznos tippekért és a helyes karbantartásért töltse le weboldalunkról a Párásító Kalauzt! | W26: kb. 0,6 kg (víz nélkül) | X26: 140 x 135 x 120 mm | Z26: max 400 ml | AB26: 37 °C | AC26: fehér | AJ26: párásító egység (párásító kamra és víztartály), használati útmutató | AL26: nem | AM26: 2 év | AN26: LMT 31920-1110 | AO26: PrismaSmart Plus | AP26: párásító kalauz letölthető | AQ26: lowenstein-prisma-aqua-parasito-feher | AR26: Löwenstein prismaAQUA fűthető párásító fehér | Alvásterápia | AS26: Gyári fűthető Löwenstein prismaAQUA párásító fehér színben, prisma SMART és SMART Plus készülékekhez. Szájszárazság ellen, optimális éjszakai páratartalom. | AV26: =VLOOKUP(I26, Kiegészítő_Mátrix!C:E, 3, FALSE) -> Prisma kiegészítők
B27: 2. | C27: Párásítók | I27: WM 29680 | J27: Prisma Aqua párásító fekete | K27: Engedélyezett | L27: Löwenstein | M27: 80010 | N27: 40005 | O27: 42005 | P27: - | Q27: profi | R27: Fűthető párásító prisma SMART, prisma 20A CPAP készülékekhez, valamint a prisma BiPAP (25S , 30ST és CR) készülékekhez, fekete színben. | S27: A prismaAQUA fűthető párásító a terápiás komfort növelésének kulcsfontosságú eszköze, amely megakadályozza a légutak és a szájnyálkahártya kiszáradását. A készülékbe észrevétlenül integrálható egység fűtési intenzitása a CPAP készülék menüjéből egyszerűen szabályozható, 5 fokozatban, így a páratartalom mindig a páciens egyéni igényeihez igazítható. A tartály kialakítása lehetővé teszi a könnyű töltést és a higiénikus tisztítást. Fontos előírás, hogy a párásító használatával egyidejűleg a kerek baktériumszűrő alkalmazása tilos! Az Ön egészségének, valamint a párásító élettartamának megőrzése érdekében desztillált víz használata javasolt. További hasznos tippekért és a helyes karbantartásért töltse le weboldalunkról a Párásító Kalauzt! | W27: kb. 0,6 kg (víz nélkül) | X27: 140 x 135 x 120 mm | Z27: max 400 ml | AB27: 37 °C | AC27: fekete | AJ27: párásító egység (párásító kamra és víztartály), használati útmutató | AL27: Nem | AM27: 2 év | AN27: LMT 31785-1110; WM 29600-1; WM 29900-1; WM 29930-2; WM 29960-2110 | AO27: PrismaSmart, A20, 25S, 30ST, CR | AP27: párásító kalauz letölthető | AQ27: lowenstein-prisma-aqua-parasito-fekete | AR27: Löwenstein prismaAQUA fűthető párásító fekete | Alvásterápia | AS27: Eredeti fekete Löwenstein prismaAQUA fűthető párásító prisma SMART, 20A és BiPAP gépekhez. Hatékony megelőzés a légúti kiszáradás ellen. Rendelje meg! | AV27: =VLOOKUP(I27, Kiegészítő_Mátrix!C:E, 3, FALSE) -> Prisma kiegészítők
B28: 2. | C28: Párásítók | I28: WM 24403 | J28: SomnoAqua fűtött párásító | K28: Engedélyezett | L28: Löwenstein | M28: 80010 | N28: 40005 | O28: 42036 | P28: - | Q28: profi | R28: Fűthető párásító a korábbi SOMNObalance készülékhez. | S28: A somnoAQUA párásító a kifutott SOMNObalance készülékek dedikált kiegészítője, csak ezen típusokkal kompatibilis. Segít a terápiás levegő nedvesítésében, javítva az alvásminőséget. Fontos előírás, hogy a párásító használatával egyidejűleg a kerek baktériumszűrő alkalmazása tilos! Az Ön egészségének, valamint a párásító élettartamának megőrzése érdekében desztillált víz használata javasolt. További hasznos tippekért és a helyes karbantartásért töltse le weboldalunkról a Párásító Kalauzt! | W28: kb. 0,6 kg (víz nélkül) | X28: 140 x 150 x 100 mm | Z28: max. 300 ml | AB28: 37 °C | AC28: átlátszó | AJ28: párásító egység (párásító kamra és víztartály), használati útmutató | AL28: Nem | AM28: 2 év | AN28: WM 27420/s | AO28: Somnobalance | AP28: van SomnoBalance-éban | AQ28: lowenstein-somnoaqua-futott-parasito | AR28: Löwenstein SomnoAqua fűthető párásító | Alvásterápia | AS28: Gyári Löwenstein SomnoAqua fűthető párásító egység a SOMNObalance CPAP készülékekhez. Kellemes, meleg páratartalom és irritációmentes éjszakai légzés. | AV28: =VLOOKUP(I28, Kiegészítő_Mátrix!C:E, 3, FALSE) -> Somnobalance kiegészítők
B29: 2. | C29: Párásítók | I29: EUXH | J29: DreamStation fűthető párásító EUXH | K29: Engedélyezett | L29: Philips | M29: 80010 | N29: 40005 | O29: 42522 | P29: - | Q29: NINCS | R29: Fűthető párásító egység Philips Dreamstation készülékhez. | S29: A Philips DreamStation párásító egysége adaptív módon szabályozza a páratartalmat, figyelembe véve a környezeti hőmérséklet változásait is, így minimalizálva a gégecsőben való páralecsapódást. A tartály felnyitható fedele rendkívül könnyű tisztítást tesz lehetővé. Kompakt kialakítása révén a készülék és a párásító egységes, elegáns megjelenést kölcsönöz a hálószobában. Fontos előírás, hogy a párásító használatával egyidejűleg a kerek baktériumszűrő alkalmazása tilos! Az Ön egészségének, valamint a párásító élettartamának megőrzése érdekében desztillált víz használata javasolt. További hasznos tippekért és a helyes karbantartásért töltse le weboldalunkról a Párásító Kalauzt! | Z29: max. 325 ml | AN29: gép | AP29: magyarul - önálló file | AQ29: philips-dreamstation-futheto-parasito-euxh | AR29: Philips DreamStation fűthető párásító | Alvásterápia | AS29: Eredeti Philips DreamStation fűthető párásító egység intelligens páraszabályozással. Megszünteti a szájszárazságot és növeli az alvásterápia komfortját. | AV29: =VLOOKUP(I29, Kiegészítő_Mátrix!C:E, 3, FALSE) -> Dreamstation1 kiegészítők
B30: 2. | C30: Párásítók | I30: 122014265 | J30: Párásító AS100A készülékhez | K30: Engedélyezett | M30: 61595 | N30: NEM ELÉRHETŐ | O30: 44927 | P30: - | Q30: NINCS | R30: Fűthető párásító egység Aeonmed készülékekhez. | S30: Az Aeonmed AS100A párásító egyszerű és hatékony megoldást kínál az orr- és torokszárazság megelőzésére, 5 fokozatban. A tartály könnyen kivehető a készülékből, így a feltöltés és a tisztítás pár másodperc alatt elvégezhető. Megbízható fűtési technológiája stabil páratartalmat biztosít az éjszaka folyamán. Fontos előírás, hogy a párásító használatával egyidejűleg a kerek baktériumszűrő alkalmazása tilos! Az Ön egészségének, valamint a párásító élettartamának megőrzése érdekében desztillált víz használata javasolt. További hasznos tippekért és a helyes karbantartásért töltse le weboldalunkról a Párásító Kalauzt! | W30: 0,44 kg | X30: 87 x 148 x 99,5 mm | Z30: max. 300ml | AA30: Ki, 1-5 | AB30: 43 °C | AC30: átlátszó | AJ30: párásító egység (párásító kamra és víztartály), használati útmutató | AL30: Nem | AM30: 2 év | AN30: 112000205 | AO30: AeonMEd AS100 | AQ30: aeonmed-as100a-futheto-parasito | AR30: AeonMed AS100A fűthető párásító egység | Alvásterápia | AS30: Gyári fűthető párásító AeonMed AS100A CPAP készülékekhez. Könnyen feltölthető és tisztítható vízkamra a szivárgásmentes, párásított légúti támogatásért. | AV30: =VLOOKUP(I30, Kiegészítő_Mátrix!C:E, 3, FALSE) -> Aeonmed kiegészítők
AV31: =VLOOKUP(I31, Kiegészítő_Mátrix!C:E, 3, FALSE) -> #N/A
B32: 3. | C32: Maszkok | D32: 3.1 | E32: Orrmaszkok | H32: CARA-ORRMASZK | I32: WM 25590 | J32: Cara (XS) | K32: Engedélyezett | L32: Löwenstein | M32: 37973 | N32: 7595 | O32: 44075 | P32: XS | Q32: profi | R32: Selymes érintés és német precizitás: az ultrakönnyű kényelem új szintje. | S32: A német Löwenstein Medical CARA orrmaszkja a modern dizájn és a kiemelkedő betegkomfort találkozása. Kifejlesztésekor a cél a tökéletes illeszkedés, a csendes működés és a bőrbarát kivitel volt. A maszk pehelykönnyű, puha és hajlékony szerkezete, valamint az állítható fejpántja révén szinte észrevétlen marad az éjszaka folyamán, így ideális megoldást kínál szinte minden felhasználó számára. A CARA maszk-család kiváló minőségét a 2018-as nemzetközi Focus Open dizájn-díj is visszaigazolja. Szakmai érv: A CARA különlegessége a tökéletesített, diffúz kilégzőrendszer: a könyöknél elhelyezkedő barázdált nyílások porlasztva engedik ki a felesleges levegőt, ami így nem kelt huzatérzetet, és nem zavarja sem a beteget, sem az alvótársát. A könyökidom felső része zárt, ami megakadályozza a levegő szem felé áramlását. A maszk puha és ruganyos párnája homloktámasz nélkül is követi az arc kontúrját, így csökkentve a nyomáspontok kialakulását. A fejpánt bőrbarát textíliája OEKO-TEX STANDARD 100 minősítéssel rendelkezik, garantálva az irritációmentes viselést. Főbb előnyök: - Szuperkönnyű kivitel: Mindössze 58–60 gramm, alig érezhető az arcon. - XS méretben is elérhető: Kifejezetten alkalmas a nagyon kisméretű arcformákhoz is. - Csendes technológia: Továbbfejlesztett kilégzőrendszer a zavartalan alvásért. - Prémium anyaghasználat: Nagyon tartós váz és OEKO-TEX minősítésű textil. - Rugalmas méretezés: L-es méretű fejpánt külön is rendelhető a maximális testreszabhatóságért. | U32: 4-30hPA | W32: 58 g | X32: 72 x 112 x 70 mm | Y32: 74 ml | AI32: Méretenként | AJ32: A választott méretű orrpárna, fejpánt, maszkváz | AK32: Nem | AL32: Igen | AM32: 2 év | AN32: WM 25192; WM 25189 | AO32: CARA fejpánt, CARA orrpárna XS | AP32: hun, en, stb összevontan | AQ32: lowenstein-cara-orrmaszk-xs | AR32: Löwenstein CARA orrmaszk XS méret | Alvásterápia | AS32: Ultrakönnyű Löwenstein CARA CPAP orrmaszk XS méretben. Puha szilikonpárna, csendes kilégzés és anatómiai illeszkedés a zavartalan alvásért. Rendelje meg! | AV32: =VLOOKUP(I32, Kiegészítő_Mátrix!C:E, 3, FALSE) -> #N/A
B33: 3. | C33: Maszkok | D33: 3.1 | E33: Orrmaszkok | H33: CARA-ORRMASZK | I33: WM 25600 | J33: Cara (S/M) | K33: Engedélyezett | L33: Löwenstein | M33: 37973 | N33: 7595 | O33: 43160 | P33: S/M | Q33: profi | R33: Selymes érintés és német precizitás: az ultrakönnyű kényelem új szintje. | S33: A német Löwenstein Medical CARA orrmaszkja a modern dizájn és a kiemelkedő betegkomfort találkozása. Kifejlesztésekor a cél a tökéletes illeszkedés, a csendes működés és a bőrbarát kivitel volt. A maszk pehelykönnyű, puha és hajlékony szerkezete, valamint az állítható fejpántja révén szinte észrevétlen marad az éjszaka folyamán, így ideális megoldást kínál szinte minden felhasználó számára. A CARA maszk-család kiváló minőségét a 2018-as nemzetközi Focus Open dizájn-díj is visszaigazolja. Szakmai érv: A CARA különlegessége a tökéletesített, diffúz kilégzőrendszer: a könyöknél elhelyezkedő barázdált nyílások porlasztva engedik ki a felesleges levegőt, ami így nem kelt huzatérzetet, és nem zavarja sem a beteget, sem az alvótársát. A könyökidom felső része zárt, ami megakadályozza a levegő szem felé áramlását. A maszk puha és ruganyos párnája homloktámasz nélkül is követi az arc kontúrját, így csökkentve a nyomáspontok kialakulását. A fejpánt bőrbarát textíliája OEKO-TEX STANDARD 100 minősítéssel rendelkezik, garantálva az irritációmentes viselést. Főbb előnyök: - Szuperkönnyű kivitel: Mindössze 58–60 gramm, alig érezhető az arcon. - XS méretben is elérhető: Kifejezetten alkalmas a nagyon kisméretű arcformákhoz is. - Csendes technológia: Továbbfejlesztett kilégzőrendszer a zavartalan alvásért. - Prémium anyaghasználat: Nagyon tartós váz és OEKO-TEX minősítésű textil. - Rugalmas méretezés: L-es méretű fejpánt külön is rendelhető a maximális testreszabhatóságért. | U33: 4-30hPA | W33: 59 g | X33: 72 x 117 x 70 mm | Y33: 76 ml | AI33: Méretenként | AJ33: A választott méretű orrpárna, fejpánt, maszkváz | AK33: Nem | AL33: Igen | AM33: 2 év | AN33: WM 25192; WM 25238 | AO33: CARA fejpánt, CARA orrpárna S/M | AP33: hun, en, stb összevontan | AQ33: lowenstein-cara-orrmaszk-sm | AR33: Löwenstein CARA orrmaszk S/M méret | Alvásterápia | AS33: Ultrakönnyű Löwenstein CARA CPAP orrmaszk S/M méretben. Puha szilikonpárna, csendes kilégzés és anatómiai illeszkedés a zavartalan alvásért. Rendelje meg! | AV33: =VLOOKUP(I33, Kiegészítő_Mátrix!C:E, 3, FALSE) -> #N/A
B34: 3. | C34: Maszkok | D34: 3.1 | E34: Orrmaszkok | H34: CARA-ORRMASZK | I34: WM 25610 | J34: Cara (M/L) | K34: Engedélyezett | L34: Löwenstein | M34: 37973 | N34: 7595 | O34: 43160 | P34: M/L | Q34: profi | R34: Selymes érintés és német precizitás: az ultrakönnyű kényelem új szintje. | S34: A német Löwenstein Medical CARA orrmaszkja a modern dizájn és a kiemelkedő betegkomfort találkozása. Kifejlesztésekor a cél a tökéletes illeszkedés, a csendes működés és a bőrbarát kivitel volt. A maszk pehelykönnyű, puha és hajlékony szerkezete, valamint az állítható fejpántja révén szinte észrevétlen marad az éjszaka folyamán, így ideális megoldást kínál szinte minden felhasználó számára. A CARA maszk-család kiváló minőségét a 2018-as nemzetközi Focus Open dizájn-díj is visszaigazolja. Szakmai érv: A CARA különlegessége a tökéletesített, diffúz kilégzőrendszer: a könyöknél elhelyezkedő barázdált nyílások porlasztva engedik ki a felesleges levegőt, ami így nem kelt huzatérzetet, és nem zavarja sem a beteget, sem az alvótársát. A könyökidom felső része zárt, ami megakadályozza a levegő szem felé áramlását. A maszk puha és ruganyos párnája homloktámasz nélkül is követi az arc kontúrját, így csökkentve a nyomáspontok kialakulását. A fejpánt bőrbarát textíliája OEKO-TEX STANDARD 100 minősítéssel rendelkezik, garantálva az irritációmentes viselést. Főbb előnyök: - Szuperkönnyű kivitel: Mindössze 58–60 gramm, alig érezhető az arcon. - XS méretben is elérhető: Kifejezetten alkalmas a nagyon kisméretű arcformákhoz is. - Csendes technológia: Továbbfejlesztett kilégzőrendszer a zavartalan alvásért. - Prémium anyaghasználat: Nagyon tartós váz és OEKO-TEX minősítésű textil. - Rugalmas méretezés: L-es méretű fejpánt külön is rendelhető a maximális testreszabhatóságért. | U34: 4-30hPA | W34: 60 g | X34: 72 x 118 x 70 mm | Y34: 79 ml | AI34: Méretenként | AJ34: A választott méretű orrpárna, fejpánt, maszkváz | AK34: Nem | AL34: Igen | AM34: 2 év | AN34: WM 25192; WM 25239; | AO34: CARA fejpánt, CARA orrpárna M/L | AP34: hun, en, stb összevontan | AQ34: lowenstein-cara-orrmaszk-ml | AR34: Löwenstein CARA orrmaszk M/L méret | Alvásterápia | AS34: Ultrakönnyű Löwenstein CARA CPAP orrmaszk M/L méretben. Puha szilikonpárna, csendes kilégzés és anatómiai illeszkedés a zavartalan alvásért. Rendelje meg! | AV34: =VLOOKUP(I34, Kiegészítő_Mátrix!C:E, 3, FALSE) -> #N/A
B35: 3. | C35: Maszkok | D35: 3.1 | E35: Orrmaszkok | H35: CARA-ORRMASZK | I35: WM 25580 | J35: Cara (XL) | K35: Engedélyezett | L35: Löwenstein | M35: 37973 | N35: 7595 | P35: XL | R35: Selymes érintés és német precizitás: az ultrakönnyű kényelem új szintje. | S35: A német Löwenstein Medical CARA orrmaszkja a modern dizájn és a kiemelkedő betegkomfort találkozása. Kifejlesztésekor a cél a tökéletes illeszkedés, a csendes működés és a bőrbarát kivitel volt. A maszk pehelykönnyű, puha és hajlékony szerkezete, valamint az állítható fejpántja révén szinte észrevétlen marad az éjszaka folyamán, így ideális megoldást kínál szinte minden felhasználó számára. A CARA maszk-család kiváló minőségét a 2018-as nemzetközi Focus Open dizájn-díj is visszaigazolja. Szakmai érv: A CARA különlegessége a tökéletesített, diffúz kilégzőrendszer: a könyöknél elhelyezkedő barázdált nyílások porlasztva engedik ki a felesleges levegőt, ami így nem kelt huzatérzetet, és nem zavarja sem a beteget, sem az alvótársát. A könyökidom felső része zárt, ami megakadályozza a levegő szem felé áramlását. A maszk puha és ruganyos párnája homloktámasz nélkül is követi az arc kontúrját, így csökkentve a nyomáspontok kialakulását. A fejpánt bőrbarát textíliája OEKO-TEX STANDARD 100 minősítéssel rendelkezik, garantálva az irritációmentes viselést. Főbb előnyök: - Szuperkönnyű kivitel: Mindössze 58–60 gramm, alig érezhető az arcon. - XS méretben is elérhető: Kifejezetten alkalmas a nagyon kisméretű arcformákhoz is. - Csendes technológia: Továbbfejlesztett kilégzőrendszer a zavartalan alvásért. - Prémium anyaghasználat: Nagyon tartós váz és OEKO-TEX minősítésű textil. - Rugalmas méretezés: L-es méretű fejpánt külön is rendelhető a maximális testreszabhatóságért. | U35: 4-30hPA | W35: 69 g | X35: 70 x 125 x 75 mm | Y35: 98 ml | AI35: Méretenként | AJ35: A választott méretű orrpárna, fejpánt, maszkváz | AK35: Nem | AL35: Igen | AM35: 2 év | AN35: WM 25192; WM 25576 | AO35: CARA fejpánt, CARA orrpárna XL | AP35: hun, en, stb összevontan | AQ35: lowenstein-cara-orrmaszk-xl | AR35: Löwenstein CARA orrmaszk XL méret | Alvásterápia | AS35: Ultrakönnyű Löwenstein CARA CPAP orrmaszk XL méretben. Puha szilikonpárna, csendes kilégzés és anatómiai illeszkedés a zavartalan alvásért. Rendelje meg! | AV35: =VLOOKUP(I35, Kiegészítő_Mátrix!C:E, 3, FALSE) -> #N/A
B36: 3. | C36: Maszkok | D36: 3.1 | E36: Orrmaszkok | H36: J.EASY-ORRMASZK | I36: WM 25510 | J36: Joyce Easy (S) | K36: Engedélyezett | L36: Löwenstein | M36: 39370 | N36: 8992 | O36: 41640 | P36: S | Q36: profi | R36: A stabilitás és az egyéni testreszabhatóság bajnoka – az egyik legnépszerűbb választásunk. | S36: A Löwenstein Medical JOYCEeasy orrmaszk az „intelligens választás” az alvásterápiában. Minden részletében az egyszerűséget, a tartósságot és a kényelmet képviseli. Úgy tervezték, hogy optimális illeszkedése révén minimalizálja a szivárgást, ezzel növelve a terápia hatékonyságát. A maszk használata rendkívül praktikus: az egyszer beállított fejpánt rögzítése a színkódolt kapcsok segítségével minden alkalommal gyors és magabiztos marad, segítve a pácienst a helyes felhelyezésben. Szakmai érv: A JOYCEeasy legfontosabb megkülönböztető jegye a hagyományos szilikon maszkokkal szemben az orrpárnán és a homloktámaszon alkalmazott, selymesen puha SilkTec bevonat. Ez a bőrbarát réteg drasztikusan csökkenti a szilikon és az arcbőr közötti súrlódást, megelőzve a pirosságot és az irritációt. A maszk továbbfejlesztett, csendes kilégzőrendszere és a 360 fokban mozgó gömbcsatlakozása biztosítja a páciens mozgásszabadságát és az alvótárs zavartalan pihenését. A kialakításnak köszönhetően a nyomáspontok egyenletesen oszlanak el, így magasabb nyomáson is kényelmes marad. Főbb előnyök: - SilkTec technológia: Selymesen puha tapintás és irritációmentes viselet az orrpárnán és a homloktámaszon. - Intuitív rögzítés: Színkódolt kapcsok segítik a gyors és hibamentes felhelyezést. - Tökéletes illeszkedés: Stabil illeszkedés, amely tehermentesíti az érzékeny nyomáspontokat. - Csendes működés: Optimalizált kilégzőrendszer a zajmentes éjszakákért. - Precíz méretezés: S, M és L méretben is elérhető a pontos anatómiai illeszkedés érdekében. | U36: 4-30hPA | W36: 94 g | X36: kb. 100 x 100 x 80 mm | Y36: 100 ml | AI36: Méretenként | AJ36: A választott méretű orrpárna, fejpánt, maszkváz | AK36: Nem | AL36: Nem | AM36: 2 év | AN36: WM 25505; WM 26801; WM 26803; | AO36: J.Easy fejpánt, J.One/Easy homloktámasz, J.Easy orrpárna S | AP36: hun, en, stb összevontan | AQ36: lowenstein-joyce-easy-orrmaszk-s | AR36: Löwenstein JOYCE Easy orrmaszk S méret | Alvásterápia | AS36: Klasszikus, rendkívül stabil Löwenstein JOYCE Easy CPAP orrmaszk S méretben. Állítható homloktámasz, csendes szelep és szivárgásmentes illeszkedés. | AV36: =VLOOKUP(I36, Kiegészítő_Mátrix!C:E, 3, FALSE) -> #N/A
B37: 3. | C37: Maszkok | D37: 3.1 | E37: Orrmaszkok | H37: J.EASY-ORRMASZK | I37: WM 25520 | J37: Joyce Easy (M) | K37: Engedélyezett | L37: Löwenstein | M37: 39370 | N37: 8992 | O37: 41640 | P37: M | Q37: profi | R37: A stabilitás és az egyéni testreszabhatóság bajnoka – az egyik legnépszerűbb választásunk. | S37: A Löwenstein Medical JOYCEeasy orrmaszk az „intelligens választás” az alvásterápiában. Minden részletében az egyszerűséget, a tartósságot és a kényelmet képviseli. Úgy tervezték, hogy optimális illeszkedése révén minimalizálja a szivárgást, ezzel növelve a terápia hatékonyságát. A maszk használata rendkívül praktikus: az egyszer beállított fejpánt rögzítése a színkódolt kapcsok segítségével minden alkalommal gyors és magabiztos marad, segítve a pácienst a helyes felhelyezésben. Szakmai érv: A JOYCEeasy legfontosabb megkülönböztető jegye a hagyományos szilikon maszkokkal szemben az orrpárnán és a homloktámaszon alkalmazott, selymesen puha SilkTec bevonat. Ez a bőrbarát réteg drasztikusan csökkenti a szilikon és az arcbőr közötti súrlódást, megelőzve a pirosságot és az irritációt. A maszk továbbfejlesztett, csendes kilégzőrendszere és a 360 fokban mozgó gömbcsatlakozása biztosítja a páciens mozgásszabadságát és az alvótárs zavartalan pihenését. A kialakításnak köszönhetően a nyomáspontok egyenletesen oszlanak el, így magasabb nyomáson is kényelmes marad. Főbb előnyök: - SilkTec technológia: Selymesen puha tapintás és irritációmentes viselet az orrpárnán és a homloktámaszon. - Intuitív rögzítés: Színkódolt kapcsok segítik a gyors és hibamentes felhelyezést. - Tökéletes illeszkedés: Stabil illeszkedés, amely tehermentesíti az érzékeny nyomáspontokat. - Csendes működés: Optimalizált kilégzőrendszer a zajmentes éjszakákért. - Precíz méretezés: S, M és L méretben is elérhető a pontos anatómiai illeszkedés érdekében. | U37: 4-30hPA | W37: 97 g | X37: kb. 105 x 110 x 80 mm | Y37: 105 ml | AI37: Méretenként | AJ37: A választott méretű orrpárna, fejpánt, maszkváz | AK37: Nem | AL37: Nem | AM37: 2 év | AN37: WM 25505; WM 26801; WM 26803; | AO37: J.Easy fejpánt, J.One/Easy homloktámasz J.Easy orrpárna M | AP37: hun, en, stb összevontan | AQ37: lowenstein-joyce-easy-orrmaszk-m | AR37: Löwenstein JOYCE Easy orrmaszk M méret | Alvásterápia | AS37: Klasszikus, rendkívül stabil Löwenstein JOYCE Easy CPAP orrmaszk M méretben. Állítható homloktámasz, csendes szelep és szivárgásmentes illeszkedés. | AV37: =VLOOKUP(I37, Kiegészítő_Mátrix!C:E, 3, FALSE) -> #N/A
B38: 3. | C38: Maszkok | D38: 3.1 | E38: Orrmaszkok | H38: J.EASY-ORRMASZK | I38: WM 25530 | J38: Joyce Easy (L) | K38: Engedélyezett | L38: Löwenstein | M38: 39370 | N38: 8992 | O38: 41640 | P38: L | Q38: profi | R38: A stabilitás és az egyéni testreszabhatóság bajnoka – az egyik legnépszerűbb választásunk. | S38: A Löwenstein Medical JOYCEeasy orrmaszk az „intelligens választás” az alvásterápiában. Minden részletében az egyszerűséget, a tartósságot és a kényelmet képviseli. Úgy tervezték, hogy optimális illeszkedése révén minimalizálja a szivárgást, ezzel növelve a terápia hatékonyságát. A maszk használata rendkívül praktikus: az egyszer beállított fejpánt rögzítése a színkódolt kapcsok segítségével minden alkalommal gyors és magabiztos marad, segítve a pácienst a helyes felhelyezésben. Szakmai érv: A JOYCEeasy legfontosabb megkülönböztető jegye a hagyományos szilikon maszkokkal szemben az orrpárnán és a homloktámaszon alkalmazott, selymesen puha SilkTec bevonat. Ez a bőrbarát réteg drasztikusan csökkenti a szilikon és az arcbőr közötti súrlódást, megelőzve a pirosságot és az irritációt. A maszk továbbfejlesztett, csendes kilégzőrendszere és a 360 fokban mozgó gömbcsatlakozása biztosítja a páciens mozgásszabadságát és az alvótárs zavartalan pihenését. A kialakításnak köszönhetően a nyomáspontok egyenletesen oszlanak el, így magasabb nyomáson is kényelmes marad. Főbb előnyök: - SilkTec technológia: Selymesen puha tapintás és irritációmentes viselet az orrpárnán és a homloktámaszon. - Intuitív rögzítés: Színkódolt kapcsok segítik a gyors és hibamentes felhelyezést. - Tökéletes illeszkedés: Stabil illeszkedés, amely tehermentesíti az érzékeny nyomáspontokat. - Csendes működés: Optimalizált kilégzőrendszer a zajmentes éjszakákért. - Precíz méretezés: S, M és L méretben is elérhető a pontos anatómiai illeszkedés érdekében. | U38: 4-30hPA | W38: 98 g | X38: kb. 110 x 120 x 80 mm | Y38: 115 ml | AI38: Méretenként | AJ38: A választott méretű orrpárna, fejpánt, maszkváz | AK38: Nem | AL38: Nem | AM38: 2 év | AN38: WM 25505; WM 26801; WM 26803; | AO38: J.Easy fejpánt, J.One/Easy homloktámasz, J.Easy orrpárna L | AP38: hun, en, stb összevontan | AQ38: lowenstein-joyce-easy-orrmaszk-l | AR38: Löwenstein JOYCE Easy orrmaszk L méret | Alvásterápia | AS38: Klasszikus, rendkívül stabil Löwenstein JOYCE Easy CPAP orrmaszk L méretben. Állítható homloktámasz, csendes szelep és szivárgásmentes illeszkedés. | AV38: =VLOOKUP(I38, Kiegészítő_Mátrix!C:E, 3, FALSE) -> #N/A
B39: 3. | C39: Maszkok | D39: 3.1 | E39: Orrmaszkok | H39: J.ONE-ORRMASZK | I39: WM 25260 | J39: Joyce One (1 méretes) | K39: Engedélyezett | L39: Löwenstein | M39: 37973 | N39: 7595 | O39: 41640 | P39: - | Q39: profi | R39: Az intelligens maszk, amely Önre van kalibrálva – méretválasztási gondok nélkül. | S39: A JOYCEone az alvásterápia „okos” maszkja: az egyetlen olyan modell, amelynél nem kell a méretvétellel bajlódni. Speciális kialakítása révén automatikusan idomul a legkülönfélébb arcformákhoz és méretekhez. Ideális választás kezdő terápiás betegeknek vagy azoknak, akik egyszerű, de megbízható megoldást keresnek szakértői segítség nélkül is. Szakmai érv: A maszk lelke az automatikus beállítású (Self-adjusting) szilikon párna és a rugalmas homloktámasz-rugó. Ezek az elemek dinamikusan követik az arc vonalait és a mozgást, így mindig az optimális feszességet tartják fenn. Nincs szükség bonyolult pántbeállításokra, a maszk „megtalálja” a helyét az arcon. Főbb előnyök: - Egyméretes (One Size): Nincs hibázási lehetőség a méretválasztásnál. - Gyors beállítás: Pillanatok alatt felhelyezhető és rögzíthető. - SilkTec kényelem: Selymes tapintású szilikon felület. - Közgyógy támogatott: Kiváló ár-érték arány és széleskörű elérhetőség. | U39: 4-30hPA | W39: 87 g | X39: 96 x 115 x 83 mm | Y39: 90 ml | AI39: Egyméretes | AJ39: A választott méretű orrpárna, fejpánt, maszkváz, homloktámasz | AK39: Nem | AL39: Igen | AM39: 2 év | AN39: WM 25255; WM 25253; WM 26801; | AO39: J.One fejpánt, J.One szilikon, J.One/Easy homloktámasz | AP39: hun, en, stb összevontan | AQ39: lowenstein-joyce-one-orrmaszk | AR39: Löwenstein JOYCE One univerzális orrmaszk | Alvásterápia | AS39: Intelligens, egyméretes Löwenstein JOYCE One CPAP orrmaszk. Automatikusan az arcformához idomuló szilikonpárna és homloktámasz a gondtalan választásért. | AV39: =VLOOKUP(I39, Kiegészítő_Mátrix!C:E, 3, FALSE) -> #N/A
